<?xml version="1.0" ?>
<sdf version="1.8">
  <model name="drift_car">
    
    <!-- ==================== CHASSIS ==================== -->
    <link name="base_link">
      <pose>0 0 0.048 0 0 0</pose>
      
      <inertial>
        <mass>1.0</mass>
        <pose>0 0 0 0 0 0</pose>
        <inertia>
          <ixx>0.00192</ixx>
          <ixy>0</ixy>
          <ixz>0</ixz>
          <iyy>0.00763</iyy>
          <iyz>0</iyz>
          <izz>0.00938</izz>
        </inertia>
      </inertial>
      
      <visual name="chassis_visual">
        <geometry>
          <box>
            <size>0.30 0.15 0.04</size>
          </box>
        </geometry>
        <material>
          <ambient>0.1 0.1 0.4 1</ambient>
          <diffuse>0.2 0.2 0.6 1</diffuse>
          <specular>0.3 0.3 0.3 1</specular>
        </material>
      </visual>
      
      <collision name="chassis_collision">
        <geometry>
          <box>
            <size>0.30 0.15 0.04</size>
          </box>
        </geometry>
      </collision>
    </link>

    <!-- ==================== REAR LEFT WHEEL ==================== -->
    <link name="rear_left_wheel">
      <pose relative_to="rear_left_wheel_joint">0 0 0 0 0 0</pose>
      
      <inertial>
        <mass>0.125</mass>
        <inertia>
          <ixx>0.000038</ixx>
          <ixy>0</ixy>
          <ixz>0</ixz>
          <iyy>0.000038</iyy>
          <iyz>0</iyz>
          <izz>0.000068</izz>
        </inertia>
      </inertial>
      
      <visual name="visual">
        <geometry>
          <cylinder>
            <radius>0.033</radius>
            <length>0.02</length>
          </cylinder>
        </geometry>
        <material>
          <ambient>0.2 0.2 0.2 1</ambient>
          <diffuse>0.3 0.3 0.3 1</diffuse>
        </material>
      </visual>
      
      <collision name="collision">
        <geometry>
          <sphere>
            <radius>0.033</radius>
          </sphere>
        </geometry>
        <surface>
          <friction>
            <ode>
              <mu>0.3</mu>
              <mu2>0.15</mu2>
              <slip1>0.1</slip1>
              <slip2>0.3</slip2>
            </ode>
          </friction>
        </surface>
      </collision>
    </link>
    
    <joint name="rear_left_wheel_joint" type="revolute">
      <pose relative_to="base_link">-0.13 0.09 -0.015 -1.5708 0 0</pose>
      <parent>base_link</parent>
      <child>rear_left_wheel</child>
      <axis>
        <xyz>0 0 1</xyz>
        <limit>
          <lower>-1.79769e+308</lower>
          <upper>1.79769e+308</upper>
          <effort>10</effort>
          <velocity>100</velocity>
        </limit>
        <dynamics>
          <damping>0.001</damping>
          <friction>0.001</friction>
        </dynamics>
      </axis>
    </joint>

    <!-- ==================== REAR RIGHT WHEEL ==================== -->
    <link name="rear_right_wheel">
      <pose relative_to="rear_right_wheel_joint">0 0 0 0 0 0</pose>
      
      <inertial>
        <mass>0.125</mass>
        <inertia>
          <ixx>0.000038</ixx>
          <ixy>0</ixy>
          <ixz>0</ixz>
          <iyy>0.000038</iyy>
          <iyz>0</iyz>
          <izz>0.000068</izz>
        </inertia>
      </inertial>
      
      <visual name="visual">
        <geometry>
          <cylinder>
            <radius>0.033</radius>
            <length>0.02</length>
          </cylinder>
        </geometry>
        <material>
          <ambient>0.2 0.2 0.2 1</ambient>
          <diffuse>0.3 0.3 0.3 1</diffuse>
        </material>
      </visual>
      
      <collision name="collision">
        <geometry>
          <sphere>
            <radius>0.033</radius>
          </sphere>
        </geometry>
        <surface>
          <friction>
            <ode>
              <mu>0.3</mu>
              <mu2>0.15</mu2>
              <slip1>0.1</slip1>
              <slip2>0.3</slip2>
            </ode>
          </friction>
        </surface>
      </collision>
    </link>
    
    <joint name="rear_right_wheel_joint" type="revolute">
      <pose relative_to="base_link">-0.13 -0.09 -0.015 -1.5708 0 0</pose>
      <parent>base_link</parent>
      <child>rear_right_wheel</child>
      <axis>
        <xyz>0 0 1</xyz>
        <limit>
          <lower>-1.79769e+308</lower>
          <upper>1.79769e+308</upper>
          <effort>10</effort>
          <velocity>100</velocity>
        </limit>
        <dynamics>
          <damping>0.001</damping>
          <friction>0.001</friction>
        </dynamics>
      </axis>
    </joint>

    <!-- ==================== FRONT LEFT STEERING + WHEEL ==================== -->
    <link name="front_left_steering_link">
      <pose relative_to="front_left_steering_joint">0 0 0 0 0 0</pose>
      
      <inertial>
        <mass>0.01</mass>
        <inertia>
          <ixx>0.000001</ixx>
          <ixy>0</ixy>
          <ixz>0</ixz>
          <iyy>0.000001</iyy>
          <iyz>0</iyz>
          <izz>0.000001</izz>
        </inertia>
      </inertial>
    </link>
    
    <joint name="front_left_steering_joint" type="revolute">
      <pose relative_to="base_link">0.13 0.09 -0.015 0 0 0</pose>
      <parent>base_link</parent>
      <child>front_left_steering_link</child>
      <axis>
        <xyz>0 0 1</xyz>
        <limit>
          <lower>-0.6</lower>
          <upper>0.6</upper>
          <effort>10</effort>
          <velocity>5</velocity>
        </limit>
        <dynamics>
          <damping>0.01</damping>
          <friction>0.0</friction>
        </dynamics>
      </axis>
    </joint>
    
    <link name="front_left_wheel">
      <pose relative_to="front_left_wheel_joint">0 0 0 0 0 0</pose>
      
      <inertial>
        <mass>0.125</mass>
        <inertia>
          <ixx>0.000038</ixx>
          <ixy>0</ixy>
          <ixz>0</ixz>
          <iyy>0.000038</iyy>
          <iyz>0</iyz>
          <izz>0.000068</izz>
        </inertia>
      </inertial>
      
      <visual name="visual">
        <geometry>
          <cylinder>
            <radius>0.033</radius>
            <length>0.02</length>
          </cylinder>
        </geometry>
        <material>
          <ambient>0.2 0.2 0.2 1</ambient>
          <diffuse>0.3 0.3 0.3 1</diffuse>
        </material>
      </visual>
      
      <collision name="collision">
        <geometry>
          <sphere>
            <radius>0.033</radius>
          </sphere>
        </geometry>
        <surface>
          <friction>
            <ode>
              <mu>1.0</mu>
              <mu2>1.0</mu2>
              <slip1>0.0</slip1>
              <slip2>0.0</slip2>
            </ode>
          </friction>
        </surface>
      </collision>
    </link>
    
    <joint name="front_left_wheel_joint" type="revolute">
      <pose relative_to="front_left_steering_link">0 0 0 -1.5708 0 0</pose>
      <parent>front_left_steering_link</parent>
      <child>front_left_wheel</child>
      <axis>
        <xyz>0 0 1</xyz>
        <limit>
          <lower>-1.79769e+308</lower>
          <upper>1.79769e+308</upper>
          <effort>0</effort>
          <velocity>100</velocity>
        </limit>
        <dynamics>
          <damping>0.0001</damping>
          <friction>0.0001</friction>
        </dynamics>
      </axis>
    </joint>

    <!-- ==================== FRONT RIGHT STEERING + WHEEL ==================== -->
    <link name="front_right_steering_link">
      <pose relative_to="front_right_steering_joint">0 0 0 0 0 0</pose>
      
      <inertial>
        <mass>0.01</mass>
        <inertia>
          <ixx>0.000001</ixx>
          <ixy>0</ixy>
          <ixz>0</ixz>
          <iyy>0.000001</iyy>
          <iyz>0</iyz>
          <izz>0.000001</izz>
        </inertia>
      </inertial>
    </link>
    
    <joint name="front_right_steering_joint" type="revolute">
      <pose relative_to="base_link">0.13 -0.09 -0.015 0 0 0</pose>
      <parent>base_link</parent>
      <child>front_right_steering_link</child>
      <axis>
        <xyz>0 0 1</xyz>
        <limit>
          <lower>-0.6</lower>
          <upper>0.6</upper>
          <effort>10</effort>
          <velocity>5</velocity>
        </limit>
        <dynamics>
          <damping>0.01</damping>
          <friction>0.0</friction>
        </dynamics>
      </axis>
    </joint>
    
    <link name="front_right_wheel">
      <pose relative_to="front_right_wheel_joint">0 0 0 0 0 0</pose>
      
      <inertial>
        <mass>0.125</mass>
        <inertia>
          <ixx>0.000038</ixx>
          <ixy>0</ixy>
          <ixz>0</ixz>
          <iyy>0.000038</iyy>
          <iyz>0</iyz>
          <izz>0.000068</izz>
        </inertia>
      </inertial>
      
      <visual name="visual">
        <geometry>
          <cylinder>
            <radius>0.033</radius>
            <length>0.02</length>
          </cylinder>
        </geometry>
        <material>
          <ambient>0.2 0.2 0.2 1</ambient>
          <diffuse>0.3 0.3 0.3 1</diffuse>
        </material>
      </visual>
      
      <collision name="collision">
        <geometry>
          <sphere>
            <radius>0.033</radius>
          </sphere>
        </geometry>
        <surface>
          <friction>
            <ode>
              <mu>1.0</mu>
              <mu2>1.0</mu2>
              <slip1>0.0</slip1>
              <slip2>0.0</slip2>
            </ode>
          </friction>
        </surface>
      </collision>
    </link>
    
    <joint name="front_right_wheel_joint" type="revolute">
      <pose relative_to="front_right_steering_link">0 0 0 -1.5708 0 0</pose>
      <parent>front_right_steering_link</parent>
      <child>front_right_wheel</child>
      <axis>
        <xyz>0 0 1</xyz>
        <limit>
          <lower>-1.79769e+308</lower>
          <upper>1.79769e+308</upper>
          <effort>0</effort>
          <velocity>100</velocity>
        </limit>
        <dynamics>
          <damping>0.0001</damping>
          <friction>0.0001</friction>
        </dynamics>
      </axis>
    </joint>

    <!-- ==================== ACKERMANN STEERING PLUGIN ==================== -->
    <!-- 
      Subscribes to: /model/drift_car/cmd_vel (gz.msgs.Twist)
      Publishes to:  /model/drift_car/odometry (gz.msgs.Odometry)
      
      Vehicle parameters:
        wheel_base:       0.26 m (front to rear axle)
        wheel_separation: 0.18 m (left to right wheel center)
        kingpin_width:    0.16 m (steering pivot to pivot)
        wheel_radius:     0.033 m
    -->
    <plugin
      filename="gz-sim-ackermann-steering-system"
      name="gz::sim::systems::AckermannSteering">
      
      <!-- Drive wheels (rear) -->
      <left_joint>rear_left_wheel_joint</left_joint>
      <right_joint>rear_right_wheel_joint</right_joint>
      
      <!-- Steering joints (front) -->
      <left_steering_joint>front_left_steering_joint</left_steering_joint>
      <right_steering_joint>front_right_steering_joint</right_steering_joint>
      
      <!-- Geometry -->
      <wheel_base>0.26</wheel_base>
      <wheel_separation>0.18</wheel_separation>
      <kingpin_width>0.16</kingpin_width>
      <wheel_radius>0.033</wheel_radius>
      <steering_limit>0.6</steering_limit>
      
      <!-- Velocity limits -->
      <min_velocity>-3.0</min_velocity>
      <max_velocity>3.0</max_velocity>
      <min_acceleration>-2.0</min_acceleration>
      <max_acceleration>2.0</max_acceleration>
      
      <!-- Odometry -->
      <odom_publish_frequency>50</odom_publish_frequency>
      <odom_topic>odometry</odom_topic>
      <tf_topic>tf</tf_topic>
      <frame_id>odom</frame_id>
      <child_frame_id>base_link</child_frame_id>
      
    </plugin>
    
    <!-- Publish joint states for monitoring -->
    <plugin
      filename="gz-sim-joint-state-publisher-system"
      name="gz::sim::systems::JointStatePublisher">
      <joint_name>front_left_steering_joint</joint_name>
      <joint_name>front_right_steering_joint</joint_name>
      <joint_name>front_left_wheel_joint</joint_name>
      <joint_name>front_right_wheel_joint</joint_name>
      <joint_name>rear_left_wheel_joint</joint_name>
      <joint_name>rear_right_wheel_joint</joint_name>
    </plugin>

  </model>
</sdf>